<?xml version="1.0"?>
<robot name="amazingRobot">

  <material name="blue">
    <color rgba="0 0 0.8 1"/>
  </material>
  <material name="black">
    <color rgba="0 0 0 1"/>
  </material>
  <material name="white">
    <color rgba="1 1 1 1"/>
  </material>

  
<link name="base">
  <visual>
    <geometry>
      <box size="0.94 0.78 1.98"/>
    </geometry>
    <material name="blue"/>
  </visual>
</link>

<link name="laser_vert_bottom">
    <visual>
      <geometry>
        <box size="0.062 0.062 0.087"/>
      </geometry>
      <origin rpy="3.1355 -1.3045 0.0025" xyz="0.3158 -0.0021 0.5100"/>
      <material name="white"/>
    </visual>
  </link>

<link name="laser_vert_top_right">
    <visual>
      <geometry>
        <box size="0.062 0.062 0.087"/>
      </geometry>
      <origin rpy="-1.1760 0.6313 -1.9377" xyz="0.2978 -0.1450 1.8451"/>
      <material name="white"/>
    </visual>
  </link>

<link name="laser_vert_top_left">
    <visual>
      <geometry>
        <box size="0.062 0.062 0.087"/>
      </geometry>
      <origin rpy="1.1780 0.6198 1.9560" xyz="0.2997 0.1531 1.8443"/>
      <material name="white"/>
    </visual>
  </link>


<link name="laser_horiz">
    <visual>
      <parent link="base"/>
      <geometry>
        <cylinder length="0.072" radius="0.052"/>
      </geometry>
	<origin rpy="-0.0012 0.1146 -0.0015" xyz="0.2325 0.0001 1.9201"/>
      <material name="white"/>
    </visual>
  </link>
<link name="wheel_left">
    <visual>
      <geometry>
        <cylinder length="0.05" radius="0.2"/>
      </geometry>
	<origin rpy="-pi/2 0.0 0.0" xyz="-0.10 0.4 0.0"/>
      <material name="white"/>
    </visual>
  </link>

<joint name="one" type="continuous">
<parent link="base"/>
<child link="laser_vert_bottom"/>
</joint>

<joint name="two" type="continuous">
<parent link="base"/>
<child link="laser_vert_top_right"/>
</joint>

<joint name="three" type="continuous">
<parent link="base"/>
<child link="laser_vert_top_left"/>
</joint>

<joint name="four" type="continuous">
<parent link="base"/>
<child link="laser_horiz"/>
</joint>

<joint name="five" type="fixed">
<parent link="base"/>
<child link="wheel_left"/>
</joint>
</robot>
  
