<?xml version="1.0"?>
<robot xmlns:xacro="http://www.ros.org/wiki/xacro" name="amazingRobot">

  <material name="blue">
    <color rgba="0 0 0.8 1"/>
  </material>
  <material name="black">
    <color rgba="0 0 0 1"/>
  </material>
  <material name="white">
    <color rgba="1 1 1 1"/>
  </material>

  
<link name="base">
  <visual>
    <geometry>
      <box size="0.94 0.78 1.98"/>
    </geometry>
    <material name="blue"/>
  </visual>
</link>

<!--<link name="laser_vert_bottom">
    <visual>
      <geometry>
        <box size="0.062 0.062 0.087"/>
      </geometry>
      <origin rpy="3.1355 -1.3045 0.0025" xyz="0.3158 -0.0021 0.5100"/>
      <material name="white"/>
    </visual>
  </link>-->

<!--<link name="laser_vert_top_right">
    <visual>
      <geometry>
        <box size="0.062 0.062 0.087"/>
      </geometry>
      <origin rpy="-1.1760 0.6313 -1.9377" xyz="0.2978 -0.1450 1.8451"/>
      <material name="white"/>
    </visual>
  </link>-->

<!--<link name="laser_vert_top_left">
    <visual>
      <geometry>
        <box size="0.062 0.062 0.087"/>
      </geometry>
      <origin rpy="1.1780 0.6198 1.9560" xyz="0.2997 0.1531 1.8443"/>
      <material name="white"/>
    </visual>
  </link>-->


<!--<link name="laser_horiz">
    <visual>
      <parent link="base"/>
      <geometry>
        <cylinder length="0.072" radius="0.052"/>
      </geometry>
	<origin rpy="-0.0012 0.1146 -0.0015" xyz="0.2325 0.0001 1.9201"/>
      <material name="white"/>
    </visual>
  </link>-->


<joint name="one" type="continuous">
<parent link="base"/>
<child link="laser_vert_bottom"/>
</joint>

<!--<joint name="two" type="continuous">
<parent link="base"/>
<child link="laser_vert_top_right"/>
</joint>-->

<!--<joint name="three" type="continuous">
<parent link="base"/>
<child link="laser_vert_top_left"/>
</joint>-->

<!--<joint name="four" type="continuous">
<parent link="base"/>
<child link="laser_horiz"/>
</joint>-->
<!--<xacro:macro name="xacro_name2" params="suffix reflect">-->

<link name="wheel_center">
    <visual>
      <geometry>
        <cylinder length="0.05" radius="0.15"/>
      </geometry>
		<origin xyz="-0.10 0.0 0.0" rpy="-1.57 0.0 0.0"/>
	<!--<origin rpy="-1.57 0.0 0.0" xyz="-0.10 0.4 0.0"/>-->
      <material name="white"/>
    </visual>
  </link>

<joint name="six" type="continuous">
<parent link="base"/>
<child link="wheel_center"/>
</joint>

<!--</xacro:macro>
<xacro:xacro_name suffix="center" reflect="1" />-->


<xacro:include filename="$(find velodyne_description)/urdf/VLP-16.urdf.xacro"/>
<VLP-16 parent="base" name="laser_horiz" topic="laser_horiz/packets" hz="10"
samples="440" gpu="false">
<origin xyz="0.2325416305773505 -0.0001380069427607134 1.920122926231907" rpy="-0.0012068 0.114646 -0.0015308" />
</VLP-16>


<xacro:include filename="$(find gazebo_plugins)/test/multi_robot_scenario/xacro/laser/hokuyo.xacro"/>

<xacro:laser name="laser_vert_bottom" parent="base" xyz="0.3157894464801903
-0.002068548615034871 0.5099999434059285" rpy="3.1354753 -1.3045001 0.0024658"
meshes="package://gazebo_plugins/test/multi_robot_scenario/meshes/laser" />


<xacro:laser name="laser_vert_right" parent="base" xyz="0.2978 -0.1450 1.8451" rpy="-1.1760 0.6313 -1.9377"
meshes="package://gazebo_plugins/test/multi_robot_scenario/meshes/laser" />

<xacro:laser name="laser_vert_left" parent="base" rpy="1.1780 0.6198 1.9560" xyz="0.2997 0.1531 1.8443"
meshes="package://gazebo_plugins/test/multi_robot_scenario/meshes/laser" />


<xacro:macro name="xacro_name" params="suffix reflect">

<link name="wheel_${suffix}">
    <visual>
      <geometry>
        <cylinder length="0.05" radius="0.2"/>
      </geometry>
		<origin xyz="-0.10 ${reflect * 0.4} 0.0" rpy="-1.57 0.0 0.0"/>
	<!--<origin rpy="-1.57 0.0 0.0" xyz="-0.10 0.4 0.0"/>-->
      <material name="white"/>
    </visual>
  </link>

<joint name="five_${suffix}" type="continuous">
<parent link="base"/>
<child link="wheel_${suffix}"/>
</joint>

</xacro:macro>
<xacro:xacro_name suffix="left" reflect="1" />

<xacro:xacro_name suffix="right" reflect="-1" />
<!--<origin xyz="-0.10 ${reflect * 0.4} 0.0" />-->





</robot>
  
